Workbook

Sheet CheckoutGuard — Business plan ·
A1: CheckoutGuard — Business plan · User-supplied synthetic runtime observations
A2: Financial model (3 pages) · Main Scenario
A4: Variable / dimension | B4: Reported input tokens | C4: Reported output tokens | D4: Elapsed seconds | E4: Model decisions | F4: Screenshots | G4: Catalog-priced token estimate
A5: Run 1 | B5: =12227 -> 12227 | C5: =202 -> 202 | D5: =21.3 -> 21.3 | E5: =7 -> 7 | F5: =8 -> 8 | G5: =('CheckoutGuard — Business plan ·'!B5*'CheckoutGuard — Assumptions · C'!B5+'CheckoutGuard — Business plan ·'!C5*'CheckoutGuard — Assumptions · C'!B6)/1000000 -> 0.00315775
A6: Run 2 | B6: =12128 -> 12128 | C6: =179 -> 179 | D6: =28.92 -> 28.92 | E6: =7 -> 7 | F6: =8 -> 8 | G6: =('CheckoutGuard — Business plan ·'!B6*'CheckoutGuard — Assumptions · C'!B5+'CheckoutGuard — Business plan ·'!C6*'CheckoutGuard — Assumptions · C'!B6)/1000000 -> 0.0031215
A7: Run 3 | B7: =12335 -> 12335 | C7: =202 -> 202 | D7: =16.66 -> 16.66 | E7: =7 -> 7 | F7: =8 -> 8 | G7: =('CheckoutGuard — Business plan ·'!B7*'CheckoutGuard — Assumptions · C'!B5+'CheckoutGuard — Business plan ·'!C7*'CheckoutGuard — Assumptions · C'!B6)/1000000 -> 0.00318475

Sheet CheckoutGuard — Business pl (2)
A1: CheckoutGuard — Business plan · Pricing contribution by subscription — assumptions
A2: Financial model (3 pages) · Main Scenario
A4: Variable / dimension | B4: Monthly price | C4: Included runs | D4: Included workspaces | E4: Used runs per subscription | F4: Delivery cost per subscription | G4: Support cost per subscription | H4: Fees per subscription | I4: Contribution per subscription | J4: Unit contribution margin | K4: Full quota contribution | L4: Full quota margin
A5: Agency | B5: =299 -> 299 | C5: =2000 -> 2000 | D5: =10 -> 10 | E5: ='CheckoutGuard — Business pl (2)'!C5*'CheckoutGuard — Assumptions · C'!B17 -> 1000 | F5: ='CheckoutGuard — Business pl (2)'!E5*'CheckoutGuard — Assumptions (2)'!B12 -> 19.0856 | G5: ='CheckoutGuard — Assumptions · W'!E5/60*'CheckoutGuard — Assumptions · C'!B16 -> 30 | H5: ='CheckoutGuard — Business pl (2)'!B5*'CheckoutGuard — Assumptions · S'!B5+'CheckoutGuard — Assumptions · S'!B6 -> 9.27 | I5: ='CheckoutGuard — Business pl (2)'!B5-'CheckoutGuard — Business pl (2)'!F5-'CheckoutGuard — Business pl (2)'!G5-'CheckoutGuard — Business pl (2)'!H5 -> 240.6444 | J5: =IFERROR('CheckoutGuard — Business pl (2)'!I5/'CheckoutGuard — Business pl (2)'!B5,"") -> 0.80483077 | K5: ='CheckoutGuard — Business pl (2)'!B5-'CheckoutGuard — Business pl (2)'!C5*'CheckoutGuard — Assumptions (2)'!B12-'CheckoutGuard — Business pl (2)'!G5-'CheckoutGuard — Business pl (2)'!H5 -> 221.5588 | L5: =IFERROR('CheckoutGuard — Business pl (2)'!K5/'CheckoutGuard — Business pl (2)'!B5,"") -> 0.74099933
A6: Developer | B6: =29 -> 29 | C6: =100 -> 100 | D6: =1 -> 1 | E6: ='CheckoutGuard — Business pl (2)'!C6*'CheckoutGuard — Assumptions · C'!B17 -> 50 | F6: ='CheckoutGuard — Business pl (2)'!E6*'CheckoutGuard — Assumptions (2)'!B12 -> 0.95428 | G6: ='CheckoutGuard — Assumptions · W'!E6/60*'CheckoutGuard — Assumptions · C'!B16 -> 5 | H6: ='CheckoutGuard — Business pl (2)'!B6*'CheckoutGuard — Assumptions · S'!B5+'CheckoutGuard — Assumptions · S'!B6 -> 1.17 | I6: ='CheckoutGuard — Business pl (2)'!B6-'CheckoutGuard — Business pl (2)'!F6-'CheckoutGuard — Business pl (2)'!G6-'CheckoutGuard — Business pl (2)'!H6 -> 21.87572 | J6: =IFERROR('CheckoutGuard — Business pl (2)'!I6/'CheckoutGuard — Business pl (2)'!B6,"") -> 0.75433517 | K6: ='CheckoutGuard — Business pl (2)'!B6-'CheckoutGuard — Business pl (2)'!C6*'CheckoutGuard — Assumptions (2)'!B12-'CheckoutGuard — Business pl (2)'!G6-'CheckoutGuard — Business pl (2)'!H6 -> 20.92144 | L6: =IFERROR('CheckoutGuard — Business pl (2)'!K6/'CheckoutGuard — Business pl (2)'!B6,"") -> 0.72142897
A7: Team | B7: =99 -> 99 | C7: =500 -> 500 | D7: =3 -> 3 | E7: ='CheckoutGuard — Business pl (2)'!C7*'CheckoutGuard — Assumptions · C'!B17 -> 250 | F7: ='CheckoutGuard — Business pl (2)'!E7*'CheckoutGuard — Assumptions (2)'!B12 -> 4.7714 | G7: ='CheckoutGuard — Assumptions · W'!E7/60*'CheckoutGuard — Assumptions · C'!B16 -> 12.5 | H7: ='CheckoutGuard — Business pl (2)'!B7*'CheckoutGuard — Assumptions · S'!B5+'CheckoutGuard — Assumptions · S'!B6 -> 3.27 | I7: ='CheckoutGuard — Business pl (2)'!B7-'CheckoutGuard — Business pl (2)'!F7-'CheckoutGuard — Business pl (2)'!G7-'CheckoutGuard — Business pl (2)'!H7 -> 78.4586 | J7: =IFERROR('CheckoutGuard — Business pl (2)'!I7/'CheckoutGuard — Business pl (2)'!B7,"") -> 0.79251111 | K7: ='CheckoutGuard — Business pl (2)'!B7-'CheckoutGuard — Business pl (2)'!C7*'CheckoutGuard — Assumptions (2)'!B12-'CheckoutGuard — Business pl (2)'!G7-'CheckoutGuard — Business pl (2)'!H7 -> 73.6872 | L7: =IFERROR('CheckoutGuard — Business pl (2)'!K7/'CheckoutGuard — Business pl (2)'!B7,"") -> 0.74431515

Sheet CheckoutGuard — Business pl (3)
A1: CheckoutGuard — Business plan · Conservative base growth comparison — assumptions
A2: Financial model (3 pages) · Main Scenario
A4: Variable / dimension | B4: 2027-10 | C4: 2027-10 > CheckoutGuard — Conservative | D4: 2027-10 > CheckoutGuard — Growth | E4: 2027-11 | F4: 2027-11 > CheckoutGuard — Conservative | G4: 2027-11 > CheckoutGuard — Growth | H4: 2027-12 | I4: 2027-12 > CheckoutGuard — Conservative | J4: 2027-12 > CheckoutGuard — Growth | K4: 2028-01 | L4: 2028-01 > CheckoutGuard — Conservative | M4: 2028-01 > CheckoutGuard — Growth | N4: 2028-02 | O4: 2028-02 > CheckoutGuard — Conservative | P4: 2028-02 > CheckoutGuard — Growth | Q4: 2028-03 | R4: 2028-03 > CheckoutGuard — Conservative | S4: 2028-03 > CheckoutGuard — Growth | T4: 2028-04 | U4: 2028-04 > CheckoutGuard — Conservative | V4: 2028-04 > CheckoutGuard — Growth | W4: 2028-05 | X4: 2028-05 > CheckoutGuard — Conservative | Y4: 2028-05 > CheckoutGuard — Growth | Z4: 2028-06 | AA4: 2028-06 > CheckoutGuard — Conservative | AB4: 2028-06 > CheckoutGuard — Growth | AC4: 2028-07 | AD4: 2028-07 > CheckoutGuard — Conservative | AE4: 2028-07 > CheckoutGuard — Growth | AF4: 2028-08 | AG4: 2028-08 > CheckoutGuard — Conservative | AH4: 2028-08 > CheckoutGuard — Growth | AI4: 2028-09 | AJ4: 2028-09 > CheckoutGuard — Conservative | AK4: 2028-09 > CheckoutGuard — Growth | AL4: 2028-10 | AM4: 2028-10 > CheckoutGuard — Conservative | AN4: 2028-10 > CheckoutGuard — Growth
A5: Active subscriptions | B5: =SUM('CheckoutGuard — Forecast · Chec'!N18,'CheckoutGuard — Forecast · Chec'!N19,'CheckoutGuard — Forecast · Chec'!N20) -> 61.988286 | C5: =SUM('Model inputs'!O11,'Model inputs'!O12,'Model inputs'!O13) -> 20.683796 | D5: =SUM('Model inputs'!O15,'Model inputs'!O16,'Model inputs'!O17) -> 138.67627 | E5: =SUM('CheckoutGuard — Forecast · Chec'!O18,'CheckoutGuard — Forecast · Chec'!O19,'CheckoutGuard — Forecast · Chec'!O20) -> 68.20999 | F5: =SUM('Model inputs'!P11,'Model inputs'!P12,'Model inputs'!P13) -> 21.899606 | G5: =SUM('Model inputs'!P15,'Model inputs'!P16,'Model inputs'!P17) -> 156.04811 | H5: =SUM('CheckoutGuard — Forecast · Chec'!P18,'CheckoutGuard — Forecast · Chec'!P19,'CheckoutGuard — Forecast · Chec'!P20) -> 74.649112 | I5: =SUM('Model inputs'!Q11,'Model inputs'!Q12,'Model inputs'!Q13) -> 23.054626 | J5: =SUM('Model inputs'!Q15,'Model inputs'!Q16,'Model inputs'!Q17) -> 174.68413 | K5: =SUM('CheckoutGuard — Forecast · Chec'!Q18,'CheckoutGuard — Forecast · Chec'!Q19,'CheckoutGuard — Forecast · Chec'!Q20) -> 81.319331 | L5: =SUM('Model inputs'!R11,'Model inputs'!R12,'Model inputs'!R13) -> 24.151895 | M5: =SUM('Model inputs'!R15,'Model inputs'!R16,'Model inputs'!R17) -> 194.688 | N5: =SUM('CheckoutGuard — Forecast · Chec'!R18,'CheckoutGuard — Forecast · Chec'!R19,'CheckoutGuard — Forecast · Chec'!R20) -> 88.234928 | O5: =SUM('Model inputs'!S11,'Model inputs'!S12,'Model inputs'!S13) -> 25.1943 | P5: =SUM('Model inputs'!S15,'Model inputs'!S16,'Model inputs'!S17) -> 216.17159 | Q5: =SUM('CheckoutGuard — Forecast · Chec'!S18,'CheckoutGuard — Forecast · Chec'!S19,'CheckoutGuard — Forecast · Chec'!S20) -> 95.410815 | R5: =SUM('Model inputs'!T11,'Model inputs'!T12,'Model inputs'!T13) -> 26.184585 | S5: =SUM('Model inputs'!T15,'Model inputs'!T16,'Model inputs'!T17) -> 239.2557 | T5: =SUM('CheckoutGuard — Forecast · Chec'!T18,'CheckoutGuard — Forecast · Chec'!T19,'CheckoutGuard — Forecast · Chec'!T20) -> 102.86257 | U5: =SUM('Model inputs'!U11,'Model inputs'!U12,'Model inputs'!U13) -> 27.125356 | V5: =SUM('Model inputs'!U15,'Model inputs'!U16,'Model inputs'!U17) -> 264.07073 | W5: =SUM('CheckoutGuard — Forecast · Chec'!U18,'CheckoutGuard — Forecast · Chec'!U19,'CheckoutGuard — Forecast · Chec'!U20) -> 110.60648 | X5: =SUM('Model inputs'!V11,'Model inputs'!V12,'Model inputs'!V13) -> 28.019088 | Y5: =SUM('Model inputs'!V15,'Model inputs'!V16,'Model inputs'!V17) -> 290.75747 | Z5: =SUM('CheckoutGuard — Forecast · Chec'!V18,'CheckoutGuard — Forecast · Chec'!V19,'CheckoutGuard — Forecast · Chec'!V20) -> 118.65956 | AA5: =SUM('Model inputs'!W11,'Model inputs'!W12,'Model inputs'!W13) -> 28.868133 | AB5: =SUM('Model inputs'!W15,'Model inputs'!W16,'Model inputs'!W17) -> 319.46793 | AC5: =SUM('CheckoutGuard — Forecast · Chec'!W18,'CheckoutGuard — Forecast · Chec'!W19,'CheckoutGuard — Forecast · Chec'!W20) -> 127.03962 | AD5: =SUM('Model inputs'!X11,'Model inputs'!X12,'Model inputs'!X13) -> 29.674727 | AE5: =SUM('Model inputs'!X15,'Model inputs'!X16,'Model inputs'!X17) -> 350.36623 | AF5: =SUM('CheckoutGuard — Forecast · Chec'!X18,'CheckoutGuard — Forecast · Chec'!X19,'CheckoutGuard — Forecast · Chec'!X20) -> 135.76526 | AG5: =SUM('Model inputs'!Y11,'Model inputs'!Y12,'Model inputs'!Y13) -> 30.44099 | AH5: =SUM('Model inputs'!Y15,'Model inputs'!Y16,'Model inputs'!Y17) -> 383.62958 | AI5: =SUM('CheckoutGuard — Forecast · Chec'!Y18,'CheckoutGuard — Forecast · Chec'!Y19,'CheckoutGuard — Forecast · Chec'!Y20) -> 144.85598 | AJ5: =SUM('Model inputs'!Z11,'Model inputs'!Z12,'Model inputs'!Z13) -> 31.168941 | AK5: =SUM('Model inputs'!Z15,'Model inputs'!Z16,'Model inputs'!Z17) -> 419.44931 | AL5: =SUM('CheckoutGuard — Forecast · Chec'!Z18,'CheckoutGuard — Forecast · Chec'!Z19,'CheckoutGuard — Forecast · Chec'!Z20) -> 154.33215 | AM5: =SUM('Model inputs'!AA11,'Model inputs'!AA12,'Model inputs'!AA13) -> 31.860494 | AN5: =SUM('Model inputs'!AA15,'Model inputs'!AA16,'Model inputs'!AA17) -> 458.03203
A6: Subscription revenue | B6: =SUM('CheckoutGuard — Forecast · Chec'!N22,'CheckoutGuard — Forecast · Chec'!N23,'CheckoutGuard — Forecast · Chec'!N24) -> 5585.8333 | C6: =SUM('Model inputs'!O89,'Model inputs'!O90,'Model inputs'!O91) -> 1863.8398 | D6: =SUM('Model inputs'!O93,'Model inputs'!O94,'Model inputs'!O95) -> 12342.188 | E6: =SUM('CheckoutGuard — Forecast · Chec'!O22,'CheckoutGuard — Forecast · Chec'!O23,'CheckoutGuard — Forecast · Chec'!O24) -> 6146.478 | F6: =SUM('Model inputs'!P89,'Model inputs'!P90,'Model inputs'!P91) -> 1973.3979 | G6: =SUM('Model inputs'!P93,'Model inputs'!P94,'Model inputs'!P95) -> 13888.282 | H6: =SUM('CheckoutGuard — Forecast · Chec'!P22,'CheckoutGuard — Forecast · Chec'!P23,'CheckoutGuard — Forecast · Chec'!P24) -> 6726.7144 | I6: =SUM('Model inputs'!Q89,'Model inputs'!Q90,'Model inputs'!Q91) -> 2077.478 | J6: =SUM('Model inputs'!Q93,'Model inputs'!Q94,'Model inputs'!Q95) -> 15546.888 | K6: =SUM('CheckoutGuard — Forecast · Chec'!Q22,'CheckoutGuard — Forecast · Chec'!Q23,'CheckoutGuard — Forecast · Chec'!Q24) -> 7327.7752 | L6: =SUM('Model inputs'!R89,'Model inputs'!R90,'Model inputs'!R91) -> 2176.3541 | M6: =SUM('Model inputs'!R93,'Model inputs'!R94,'Model inputs'!R95) -> 17327.232 | N6: =SUM('CheckoutGuard — Forecast · Chec'!R22,'CheckoutGuard — Forecast · Chec'!R23,'CheckoutGuard — Forecast · Chec'!R24) -> 7950.9474 | O6: =SUM('Model inputs'!S89,'Model inputs'!S90,'Model inputs'!S91) -> 2270.2864 | P6: =SUM('Model inputs'!S93,'Model inputs'!S94,'Model inputs'!S95) -> 19239.272 | Q6: =SUM('CheckoutGuard — Forecast · Chec'!S22,'CheckoutGuard — Forecast · Chec'!S23,'CheckoutGuard — Forecast · Chec'!S24) -> 8597.5746 | R6: =SUM('Model inputs'!T89,'Model inputs'!T90,'Model inputs'!T91) -> 2359.522 | S6: =SUM('Model inputs'!T93,'Model inputs'!T94,'Model inputs'!T95) -> 21293.758 | T6: =SUM('CheckoutGuard — Forecast · Chec'!T22,'CheckoutGuard — Forecast · Chec'!T23,'CheckoutGuard — Forecast · Chec'!T24) -> 9269.0608 | U6: =SUM('Model inputs'!U89,'Model inputs'!U90,'Model inputs'!U91) -> 2444.2959 | V6: =SUM('Model inputs'!U93,'Model inputs'!U94,'Model inputs'!U95) -> 23502.295 | W6: =SUM('CheckoutGuard — Forecast · Chec'!U22,'CheckoutGuard — Forecast · Chec'!U23,'CheckoutGuard — Forecast · Chec'!U24) -> 9966.8731 | X6: =SUM('Model inputs'!V89,'Model inputs'!V90,'Model inputs'!V91) -> 2524.8311 | Y6: =SUM('Model inputs'!V93,'Model inputs'!V94,'Model inputs'!V95) -> 25877.415 | Z6: =SUM('CheckoutGuard — Forecast · Chec'!V22,'CheckoutGuard — Forecast · Chec'!V23,'CheckoutGuard — Forecast · Chec'!V24) -> 10692.545 | AA6: =SUM('Model inputs'!W89,'Model inputs'!W90,'Model inputs'!W91) -> 2601.3396 | AB6: =SUM('Model inputs'!W93,'Model inputs'!W94,'Model inputs'!W95) -> 28432.646 | AC6: =SUM('CheckoutGuard — Forecast · Chec'!W22,'CheckoutGuard — Forecast · Chec'!W23,'CheckoutGuard — Forecast · Chec'!W24) -> 11447.681 | AD6: =SUM('Model inputs'!X89,'Model inputs'!X90,'Model inputs'!X91) -> 2674.0226 | AE6: =SUM('Model inputs'!X93,'Model inputs'!X94,'Model inputs'!X95) -> 31182.595 | AF6: =SUM('CheckoutGuard — Forecast · Chec'!X22,'CheckoutGuard — Forecast · Chec'!X23,'CheckoutGuard — Forecast · Chec'!X24) -> 12233.958 | AG6: =SUM('Model inputs'!Y89,'Model inputs'!Y90,'Model inputs'!Y91) -> 2743.0715 | AH6: =SUM('Model inputs'!Y93,'Model inputs'!Y94,'Model inputs'!Y95) -> 34143.032 | AI6: =SUM('CheckoutGuard — Forecast · Chec'!Y22,'CheckoutGuard — Forecast · Chec'!Y23,'CheckoutGuard — Forecast · Chec'!Y24) -> 13053.133 | AJ6: =SUM('Model inputs'!Z89,'Model inputs'!Z90,'Model inputs'!Z91) -> 2808.6679 | AK6: =SUM('Model inputs'!Z93,'Model inputs'!Z94,'Model inputs'!Z95) -> 37330.989 | AL6: =SUM('CheckoutGuard — Forecast · Chec'!Z22,'CheckoutGuard — Forecast · Chec'!Z23,'CheckoutGuard — Forecast · Chec'!Z24) -> 13907.042 | AM6: =SUM('Model inputs'!AA89,'Model inputs'!AA90,'Model inputs'!AA91) -> 2870.9845 | AN6: =SUM('Model inputs'!AA93,'Model inputs'!AA94,'Model inputs'!AA95) -> 40764.851
A7: Contribution | B7: =SUM('CheckoutGuard — Forecast · Chec'!N38,'CheckoutGuard — Forecast · Chec'!N39,'CheckoutGuard — Forecast · Chec'!N40) -> 4421.7049 | C7: =SUM('Model inputs'!O24,'Model inputs'!O25,'Model inputs'!O26) -> 1475.402 | D7: =SUM('Model inputs'!O28,'Model inputs'!O29,'Model inputs'!O30) -> 9768.41 | E7: =SUM('CheckoutGuard — Forecast · Chec'!O38,'CheckoutGuard — Forecast · Chec'!O39,'CheckoutGuard — Forecast · Chec'!O40) -> 4865.5071 | F7: =SUM('Model inputs'!P24,'Model inputs'!P25,'Model inputs'!P26) -> 1562.1273 | G7: =SUM('Model inputs'!P28,'Model inputs'!P29,'Model inputs'!P30) -> 10992.089 | H7: =SUM('CheckoutGuard — Forecast · Chec'!P38,'CheckoutGuard — Forecast · Chec'!P39,'CheckoutGuard — Forecast · Chec'!P40) -> 5324.818 | I7: =SUM('Model inputs'!Q24,'Model inputs'!Q25,'Model inputs'!Q26) -> 1644.5164 | J7: =SUM('Model inputs'!Q28,'Model inputs'!Q29,'Model inputs'!Q30) -> 12304.818 | K7: =SUM('CheckoutGuard — Forecast · Chec'!Q38,'CheckoutGuard — Forecast · Chec'!Q39,'CheckoutGuard — Forecast · Chec'!Q40) -> 5800.6134 | L7: =SUM('Model inputs'!R24,'Model inputs'!R25,'Model inputs'!R26) -> 1722.786 | M7: =SUM('Model inputs'!R28,'Model inputs'!R29,'Model inputs'!R30) -> 13713.898 | N7: =SUM('CheckoutGuard — Forecast · Chec'!R38,'CheckoutGuard — Forecast · Chec'!R39,'CheckoutGuard — Forecast · Chec'!R40) -> 6293.9119 | O7: =SUM('Model inputs'!S24,'Model inputs'!S25,'Model inputs'!S26) -> 1797.1421 | P7: =SUM('Model inputs'!S28,'Model inputs'!S29,'Model inputs'!S30) -> 15227.21 | Q7: =SUM('CheckoutGuard — Forecast · Chec'!S38,'CheckoutGuard — Forecast · Chec'!S39,'CheckoutGuard — Forecast · Chec'!S40) -> 6805.7773 | R7: =SUM('Model inputs'!T24,'Model inputs'!T25,'Model inputs'!T26) -> 1867.7804 | S7: =SUM('Model inputs'!T28,'Model inputs'!T29,'Model inputs'!T30) -> 16853.264 | T7: =SUM('CheckoutGuard — Forecast · Chec'!T38,'CheckoutGuard — Forecast · Chec'!T39,'CheckoutGuard — Forecast · Chec'!T40) -> 7337.3209 | U7: =SUM('Model inputs'!U24,'Model inputs'!U25,'Model inputs'!U26) -> 1934.8868 | V7: =SUM('Model inputs'!U28,'Model inputs'!U29,'Model inputs'!U30) -> 18601.244 | W7: =SUM('CheckoutGuard — Forecast · Chec'!U38,'CheckoutGuard — Forecast · Chec'!U39,'CheckoutGuard — Forecast · Chec'!U40) -> 7889.704 | X7: =SUM('Model inputs'!V24,'Model inputs'!V25,'Model inputs'!V26) -> 1998.6379 | Y7: =SUM('Model inputs'!V28,'Model inputs'!V29,'Model inputs'!V30) -> 20481.068 | Z7: =SUM('CheckoutGuard — Forecast · Chec'!V38,'CheckoutGuard — Forecast · Chec'!V39,'CheckoutGuard — Forecast · Chec'!V40) -> 8464.1407 | AA7: =SUM('Model inputs'!W24,'Model inputs'!W25,'Model inputs'!W26) -> 2059.2014 | AB7: =SUM('Model inputs'!W28,'Model inputs'!W29,'Model inputs'!W30) -> 22503.444 | AC7: =SUM('CheckoutGuard — Forecast · Chec'!W38,'CheckoutGuard — Forecast · Chec'!W39,'CheckoutGuard — Forecast · Chec'!W40) -> 9061.9007 | AD7: =SUM('Model inputs'!X24,'Model inputs'!X25,'Model inputs'!X26) -> 2116.7368 | AE7: =SUM('Model inputs'!X28,'Model inputs'!X29,'Model inputs'!X30) -> 24679.932 | AF7: =SUM('CheckoutGuard — Forecast · Chec'!X38,'CheckoutGuard — Forecast · Chec'!X39,'CheckoutGuard — Forecast · Chec'!X40) -> 9684.3122 | AG7: =SUM('Model inputs'!Y24,'Model inputs'!Y25,'Model inputs'!Y26) -> 2171.3954 | AH7: =SUM('Model inputs'!Y28,'Model inputs'!Y29,'Model inputs'!Y30) -> 27023.015 | AI7: =SUM('CheckoutGuard — Forecast · Chec'!Y38,'CheckoutGuard — Forecast · Chec'!Y39,'CheckoutGuard — Forecast · Chec'!Y40) -> 10332.765 | AJ7: =SUM('Model inputs'!Z24,'Model inputs'!Z25,'Model inputs'!Z26) -> 2223.321 | AK7: =SUM('Model inputs'!Z28,'Model inputs'!Z29,'Model inputs'!Z30) -> 29546.171 | AL7: =SUM('CheckoutGuard — Forecast · Chec'!Z38,'CheckoutGuard — Forecast · Chec'!Z39,'CheckoutGuard — Forecast · Chec'!Z40) -> 11008.713 | AM7: =SUM('Model inputs'!AA24,'Model inputs'!AA25,'Model inputs'!AA26) -> 2272.6504 | AN7: =SUM('Model inputs'!AA28,'Model inputs'!AA29,'Model inputs'!AA30) -> 32263.953
A8: Contribution margin | B8: =IFERROR('CheckoutGuard — Business pl (3)'!B7/'CheckoutGuard — Business pl (3)'!B6,"") -> 0.7915927 | C8: =IFERROR('CheckoutGuard — Business pl (3)'!C7/'CheckoutGuard — Business pl (3)'!C6,"") -> 0.7915927 | D8: =IFERROR('CheckoutGuard — Business pl (3)'!D7/'CheckoutGuard — Business pl (3)'!D6,"") -> 0.791465 | E8: =IFERROR('CheckoutGuard — Business pl (3)'!E7/'CheckoutGuard — Business pl (3)'!E6,"") -> 0.7915927 | F8: =IFERROR('CheckoutGuard — Business pl (3)'!F7/'CheckoutGuard — Business pl (3)'!F6,"") -> 0.7915927 | G8: =IFERROR('CheckoutGuard — Business pl (3)'!G7/'CheckoutGuard — Business pl (3)'!G6,"") -> 0.791465 | H8: =IFERROR('CheckoutGuard — Business pl (3)'!H7/'CheckoutGuard — Business pl (3)'!H6,"") -> 0.7915927 | I8: =IFERROR('CheckoutGuard — Business pl (3)'!I7/'CheckoutGuard — Business pl (3)'!I6,"") -> 0.7915927 | ... AN8: =IFERROR('CheckoutGuard — Business pl (3)'!AN7/'CheckoutGuard — Business pl (3)'!AN6,"") -> 0.791465
A9: Operating result | B9: ='CheckoutGuard — Business pl (3)'!B7-'CheckoutGuard — Assumptions (2)'!B13 -> -2378.2951 | C9: ='CheckoutGuard — Business pl (3)'!C7-'Model inputs'!AB37 -> -5324.598 | D9: ='CheckoutGuard — Business pl (3)'!D7-'Model inputs'!AB38 -> 2968.41 | E9: ='CheckoutGuard — Business pl (3)'!E7-'CheckoutGuard — Assumptions (2)'!B13 -> -1934.4929 | F9: ='CheckoutGuard — Business pl (3)'!F7-'Model inputs'!AB37 -> -5237.8727 | G9: ='CheckoutGuard — Business pl (3)'!G7-'Model inputs'!AB38 -> 4192.0887 | H9: ='CheckoutGuard — Business pl (3)'!H7-'CheckoutGuard — Assumptions (2)'!B13 -> -1475.182 | I9: ='CheckoutGuard — Business pl (3)'!I7-'Model inputs'!AB37 -> -5155.4836 | J9: ='CheckoutGuard — Business pl (3)'!J7-'Model inputs'!AB38 -> 5504.8177 | K9: ='CheckoutGuard — Business pl (3)'!K7-'CheckoutGuard — Assumptions (2)'!B13 -> -999.38661 | L9: ='CheckoutGuard — Business pl (3)'!L7-'Model inputs'!AB37 -> -5077.214 | M9: ='CheckoutGuard — Business pl (3)'!M7-'Model inputs'!AB38 -> 6913.8977 | N9: ='CheckoutGuard — Business pl (3)'!N7-'CheckoutGuard — Assumptions (2)'!B13 -> -506.08811 | O9: ='CheckoutGuard — Business pl (3)'!O7-'Model inputs'!AB37 -> -5002.8579 | P9: ='CheckoutGuard — Business pl (3)'!P7-'Model inputs'!AB38 -> 8427.2103 | Q9: ='CheckoutGuard — Business pl (3)'!Q7-'CheckoutGuard — Assumptions (2)'!B13 -> 5.7772852 | R9: ='CheckoutGuard — Business pl (3)'!R7-'Model inputs'!AB37 -> -4932.2196 | S9: ='CheckoutGuard — Business pl (3)'!S7-'Model inputs'!AB38 -> 10053.264 | T9: ='CheckoutGuard — Business pl (3)'!T7-'CheckoutGuard — Assumptions (2)'!B13 -> 537.32085 | U9: ='CheckoutGuard — Business pl (3)'!U7-'Model inputs'!AB37 -> -4865.1132 | V9: ='CheckoutGuard — Business pl (3)'!V7-'Model inputs'!AB38 -> 11801.244 | W9: ='CheckoutGuard — Business pl (3)'!W7-'CheckoutGuard — Assumptions (2)'!B13 -> 1089.704 | X9: ='CheckoutGuard — Business pl (3)'!X7-'Model inputs'!AB37 -> -4801.3621 | Y9: ='CheckoutGuard — Business pl (3)'!Y7-'Model inputs'!AB38 -> 13681.068 | Z9: ='CheckoutGuard — Business pl (3)'!Z7-'CheckoutGuard — Assumptions (2)'!B13 -> 1664.1407 | AA9: ='CheckoutGuard — Business pl (3)'!AA7-'Model inputs'!AB37 -> -4740.7986 | AB9: ='CheckoutGuard — Business pl (3)'!AB7-'Model inputs'!AB38 -> 15703.444 | AC9: ='CheckoutGuard — Business pl (3)'!AC7-'CheckoutGuard — Assumptions (2)'!B13 -> 2261.9007 | AD9: ='CheckoutGuard — Business pl (3)'!AD7-'Model inputs'!AB37 -> -4683.2632 | AE9: ='CheckoutGuard — Business pl (3)'!AE7-'Model inputs'!AB38 -> 17879.932 | AF9: ='CheckoutGuard — Business pl (3)'!AF7-'CheckoutGuard — Assumptions (2)'!B13 -> 2884.3122 | AG9: ='CheckoutGuard — Business pl (3)'!AG7-'Model inputs'!AB37 -> -4628.6046 | AH9: ='CheckoutGuard — Business pl (3)'!AH7-'Model inputs'!AB38 -> 20223.015 | AI9: ='CheckoutGuard — Business pl (3)'!AI7-'CheckoutGuard — Assumptions (2)'!B13 -> 3532.7647 | AJ9: ='CheckoutGuard — Business pl (3)'!AJ7-'Model inputs'!AB37 -> -4576.679 | AK9: ='CheckoutGuard — Business pl (3)'!AK7-'Model inputs'!AB38 -> 22746.171 | AL9: ='CheckoutGuard — Business pl (3)'!AL7-'CheckoutGuard — Assumptions (2)'!B13 -> 4208.7128 | AM9: ='CheckoutGuard — Business pl (3)'!AM7-'Model inputs'!AB37 -> -4527.3496 | AN9: ='CheckoutGuard — Business pl (3)'!AN7-'Model inputs'!AB38 -> 25463.953
A10: Break-even subscriptions | B10: =IFERROR(CEILING('CheckoutGuard — Assumptions (2)'!B13/('CheckoutGuard — Business pl (3)'!B7/'CheckoutGuard — Business pl (3)'!B5),1),"") -> 96 | C10: =IFERROR(CEILING('Model inputs'!AB37/('CheckoutGuard — Business pl (3)'!C7/'CheckoutGuard — Business pl (3)'!C5),1),"") -> 96 | D10: =IFERROR(CEILING('Model inputs'!AB38/('CheckoutGuard — Business pl (3)'!D7/'CheckoutGuard — Business pl (3)'!D5),1),"") -> 97 | E10: =IFERROR(CEILING('CheckoutGuard — Assumptions (2)'!B13/('CheckoutGuard — Business pl (3)'!E7/'CheckoutGuard — Business pl (3)'!E5),1),"") -> 96 | F10: =IFERROR(CEILING('Model inputs'!AB37/('CheckoutGuard — Business pl (3)'!F7/'CheckoutGuard — Business pl (3)'!F5),1),"") -> 96 | G10: =IFERROR(CEILING('Model inputs'!AB38/('CheckoutGuard — Business pl (3)'!G7/'CheckoutGuard — Business pl (3)'!G5),1),"") -> 97 | H10: =IFERROR(CEILING('CheckoutGuard — Assumptions (2)'!B13/('CheckoutGuard — Business pl (3)'!H7/'CheckoutGuard — Business pl (3)'!H5),1),"") -> 96 | I10: =IFERROR(CEILING('Model inputs'!AB37/('CheckoutGuard — Business pl (3)'!I7/'CheckoutGuard — Business pl (3)'!I5),1),"") -> 96 | J10: =IFERROR(CEILING('Model inputs'!AB38/('CheckoutGuard — Business pl (3)'!J7/'CheckoutGuard — Business pl (3)'!J5),1),"") -> 97 | K10: =IFERROR(CEILING('CheckoutGuard — Assumptions (2)'!B13/('CheckoutGuard — Business pl (3)'!K7/'CheckoutGuard — Business pl (3)'!K5),1),"") -> 96 | L10: =IFERROR(CEILING('Model inputs'!AB37/('CheckoutGuard — Business pl (3)'!L7/'CheckoutGuard — Business pl (3)'!L5),1),"") -> 96 | M10: =IFERROR(CEILING('Model inputs'!AB38/('CheckoutGuard — Business pl (3)'!M7/'CheckoutGuard — Business pl (3)'!M5),1),"") -> 97 | N10: =IFERROR(CEILING('CheckoutGuard — Assumptions (2)'!B13/('CheckoutGuard — Business pl (3)'!N7/'CheckoutGuard — Business pl (3)'!N5),1),"") -> 96 | O10: =IFERROR(CEILING('Model inputs'!AB37/('CheckoutGuard — Business pl (3)'!O7/'CheckoutGuard — Business pl (3)'!O5),1),"") -> 96 | P10: =IFERROR(CEILING('Model inputs'!AB38/('CheckoutGuard — Business pl (3)'!P7/'CheckoutGuard — Business pl (3)'!P5),1),"") -> 97 | Q10: =IFERROR(CEILING('CheckoutGuard — Assumptions (2)'!B13/('CheckoutGuard — Business pl (3)'!Q7/'CheckoutGuard — Business pl (3)'!Q5),1),"") -> 96 | R10: =IFERROR(CEILING('Model inputs'!AB37/('CheckoutGuard — Business pl (3)'!R7/'CheckoutGuard — Business pl (3)'!R5),1),"") -> 96 | S10: =IFERROR(CEILING('Model inputs'!AB38/('CheckoutGuard — Business pl (3)'!S7/'CheckoutGuard — Business pl (3)'!S5),1),"") -> 97 | T10: =IFERROR(CEILING('CheckoutGuard — Assumptions (2)'!B13/('CheckoutGuard — Business pl (3)'!T7/'CheckoutGuard — Business pl (3)'!T5),1),"") -> 96 | U10: =IFERROR(CEILING('Model inputs'!AB37/('CheckoutGuard — Business pl (3)'!U7/'CheckoutGuard — Business pl (3)'!U5),1),"") -> 96 | V10: =IFERROR(CEILING('Model inputs'!AB38/('CheckoutGuard — Business pl (3)'!V7/'CheckoutGuard — Business pl (3)'!V5),1),"") -> 97 | W10: =IFERROR(CEILING('CheckoutGuard — Assumptions (2)'!B13/('CheckoutGuard — Business pl (3)'!W7/'CheckoutGuard — Business pl (3)'!W5),1),"") -> 96 | X10: =IFERROR(CEILING('Model inputs'!AB37/('CheckoutGuard — Business pl (3)'!X7/'CheckoutGuard — Business pl (3)'!X5),1),"") -> 96 | Y10: =IFERROR(CEILING('Model inputs'!AB38/('CheckoutGuard — Business pl (3)'!Y7/'CheckoutGuard — Business pl (3)'!Y5),1),"") -> 97 | Z10: =IFERROR(CEILING('CheckoutGuard — Assumptions (2)'!B13/('CheckoutGuard — Business pl (3)'!Z7/'CheckoutGuard — Business pl (3)'!Z5),1),"") -> 96 | AA10: =IFERROR(CEILING('Model inputs'!AB37/('CheckoutGuard — Business pl (3)'!AA7/'CheckoutGuard — Business pl (3)'!AA5),1),"") -> 96 | AB10: =IFERROR(CEILING('Model inputs'!AB38/('CheckoutGuard — Business pl (3)'!AB7/'CheckoutGuard — Business pl (3)'!AB5),1),"") -> 97 | AC10: =IFERROR(CEILING('CheckoutGuard — Assumptions (2)'!B13/('CheckoutGuard — Business pl (3)'!AC7/'CheckoutGuard — Business pl (3)'!AC5),1),"") -> 96 | AD10: =IFERROR(CEILING('Model inputs'!AB37/('CheckoutGuard — Business pl (3)'!AD7/'CheckoutGuard — Business pl (3)'!AD5),1),"") -> 96 | AE10: =IFERROR(CEILING('Model inputs'!AB38/('CheckoutGuard — Business pl (3)'!AE7/'CheckoutGuard — Business pl (3)'!AE5),1),"") -> 97 | AF10: =IFERROR(CEILING('CheckoutGuard — Assumptions (2)'!B13/('CheckoutGuard — Business pl (3)'!AF7/'CheckoutGuard — Business pl (3)'!AF5),1),"") -> 96 | AG10: =IFERROR(CEILING('Model inputs'!AB37/('CheckoutGuard — Business pl (3)'!AG7/'CheckoutGuard — Business pl (3)'!AG5),1),"") -> 96 | AH10: =IFERROR(CEILING('Model inputs'!AB38/('CheckoutGuard — Business pl (3)'!AH7/'CheckoutGuard — Business pl (3)'!AH5),1),"") -> 97 | AI10: =IFERROR(CEILING('CheckoutGuard — Assumptions (2)'!B13/('CheckoutGuard — Business pl (3)'!AI7/'CheckoutGuard — Business pl (3)'!AI5),1),"") -> 96 | AJ10: =IFERROR(CEILING('Model inputs'!AB37/('CheckoutGuard — Business pl (3)'!AJ7/'CheckoutGuard — Business pl (3)'!AJ5),1),"") -> 96 | AK10: =IFERROR(CEILING('Model inputs'!AB38/('CheckoutGuard — Business pl (3)'!AK7/'CheckoutGuard — Business pl (3)'!AK5),1),"") -> 97 | AL10: =IFERROR(CEILING('CheckoutGuard — Assumptions (2)'!B13/('CheckoutGuard — Business pl (3)'!AL7/'CheckoutGuard — Business pl (3)'!AL5),1),"") -> 96 | AM10: =IFERROR(CEILING('Model inputs'!AB37/('CheckoutGuard — Business pl (3)'!AM7/'CheckoutGuard — Business pl (3)'!AM5),1),"") -> 96 | AN10: =IFERROR(CEILING('Model inputs'!AB38/('CheckoutGuard — Business pl (3)'!AN7/'CheckoutGuard — Business pl (3)'!AN5),1),"") -> 97
A11: Cumulative operating result | B11: ='CheckoutGuard — Forecast · Chec'!M49+'CheckoutGuard — Business pl (3)'!B9 -> -54260.063 | C11: ='Model inputs'!N32+'CheckoutGuard — Business pl (3)'!C9 -> -71113.737 | D11: ='Model inputs'!N33+'CheckoutGuard — Business pl (3)'!D9 -> -25549.65 | E11: ='CheckoutGuard — Business pl (3)'!B11+'CheckoutGuard — Business pl (3)'!E9 -> -56194.556 | F11: ='CheckoutGuard — Business pl (3)'!C11+'CheckoutGuard — Business pl (3)'!F9 -> -76351.61 | G11: ='CheckoutGuard — Business pl (3)'!D11+'CheckoutGuard — Business pl (3)'!G9 -> -21357.561 | H11: ='CheckoutGuard — Business pl (3)'!E11+'CheckoutGuard — Business pl (3)'!H9 -> -57669.738 | I11: ='CheckoutGuard — Business pl (3)'!F11+'CheckoutGuard — Business pl (3)'!I9 -> -81507.094 | J11: ='CheckoutGuard — Business pl (3)'!G11+'CheckoutGuard — Business pl (3)'!J9 -> -15852.744 | K11: ='CheckoutGuard — Business pl (3)'!H11+'CheckoutGuard — Business pl (3)'!K9 -> -58669.125 | L11: ='CheckoutGuard — Business pl (3)'!I11+'CheckoutGuard — Business pl (3)'!L9 -> -86584.308 | ... AN11: ='CheckoutGuard — Business pl (3)'!AK11+'CheckoutGuard — Business pl (3)'!AN9 -> 137040.46

Sheet CheckoutGuard — Assumptions · C
A1: CheckoutGuard — Assumptions · Cost and growth assumptions — not actuals
A2: Financial model (3 pages) · Main Scenario
A4: Variable / dimension | B4: Value
A5: Input rate per million | B5: =0.25 -> 0.25
A6: Output rate per million | B6: =0.5 -> 0.5
A7: Provider cost multiplier | B7: =1 -> 1
A8: Extra attempt ratio | B8: =0.2 -> 0.2
A9: Timeout token allowance ratio | B9: =1 -> 1
A10: Browser seconds per attempt | B10: =45 -> 45
A11: Browser cost per hour | B11: =0.12 -> 0.12
A12: Database cost per run | B12: =0.002 -> 0.002
A13: Evidence cost per run | B13: =0.001 -> 0.001
A14: Telemetry cost per run | B14: =0.0005 -> 0.0005
A15: Support minutes per run | B15: =0.02 -> 0.02
A16: Support cost per hour | B16: =30 -> 30
A17: Run utilization | B17: =0.5 -> 0.5
A18: Prospect monthly growth | B18: =0.05 -> 0.05
A19: Monthly churn | B19: =0.03 -> 0.03
A20: Fixed app hosting per month | B20: =150 -> 150
A21: Fixed database per month | B21: =60 -> 60
A22: Fixed telemetry per month | B22: =30 -> 30
A23: Other overhead per month | B23: =60 -> 60
A24: Founder compensation per month | B24: =6000 -> 6000
A25: Sales budget per month | B25: =500 -> 500

Sheet CheckoutGuard — Assumptions · W
A1: CheckoutGuard — Assumptions · Workspace pricing options — assumptions
A2: Financial model (3 pages) · Main Scenario
A4: Variable / dimension | B4: Monthly price | C4: Included runs | D4: Included workspaces | E4: Support minutes per workspace | F4: Monthly qualified prospects | G4: Paid conversion
A5: Agency | B5: ='CheckoutGuard — Business pl (2)'!B5 -> 299 | C5: ='CheckoutGuard — Business pl (2)'!C5 -> 2000 | D5: ='CheckoutGuard — Business pl (2)'!D5 -> 10 | E5: =60 -> 60 | F5: =5 -> 5 | G5: =0.1 -> 0.1
A6: Developer | B6: ='CheckoutGuard — Business pl (2)'!B6 -> 29 | C6: ='CheckoutGuard — Business pl (2)'!C6 -> 100 | D6: ='CheckoutGuard — Business pl (2)'!D6 -> 1 | E6: =10 -> 10 | F6: =40 -> 40 | G6: =0.05 -> 0.05
A7: Team | B7: ='CheckoutGuard — Business pl (2)'!B7 -> 99 | C7: ='CheckoutGuard — Business pl (2)'!C7 -> 500 | D7: ='CheckoutGuard — Business pl (2)'!D7 -> 3 | E7: =25 -> 25 | F7: =20 -> 20 | G7: =0.1 -> 0.1

Sheet CheckoutGuard — Assumptions (2)
A1: CheckoutGuard — Assumptions · Cost per run and contribution economics — estimates
A2: Financial model (3 pages) · Main Scenario
A4: Variable / dimension | B4: Value
A5: Mean input tokens | B5: =AVERAGE('CheckoutGuard — Business plan ·'!B5,'CheckoutGuard — Business plan ·'!B6,'CheckoutGuard — Business plan ·'!B7) -> 12230
A6: Mean output tokens | B6: =AVERAGE('CheckoutGuard — Business plan ·'!C5,'CheckoutGuard — Business plan ·'!C6,'CheckoutGuard — Business plan ·'!C7) -> 194.33333
A7: Mean elapsed seconds | B7: =AVERAGE('CheckoutGuard — Business plan ·'!D5,'CheckoutGuard — Business plan ·'!D6,'CheckoutGuard — Business plan ·'!D7) -> 22.293333
A8: Known token estimate per run | B8: =('CheckoutGuard — Assumptions (2)'!B5*'CheckoutGuard — Assumptions · C'!B5+'CheckoutGuard — Assumptions (2)'!B6*'CheckoutGuard — Assumptions · C'!B6)/1000000 -> 0.0031546667
A9: AI allowance per completed run | B9: ='CheckoutGuard — Assumptions (2)'!B8*'CheckoutGuard — Assumptions · C'!B7*(1+'CheckoutGuard — Assumptions · C'!B8*'CheckoutGuard — Assumptions · C'!B9) -> 0.0037856
A10: Browser cost per completed run | B10: ='CheckoutGuard — Assumptions · C'!B10/3600*'CheckoutGuard — Assumptions · C'!B11*(1+'CheckoutGuard — Assumptions · C'!B8) -> 0.0018
A11: Support cost per run | B11: ='CheckoutGuard — Assumptions · C'!B15/60*'CheckoutGuard — Assumptions · C'!B16 -> 0.01
A12: Estimated cost per completed run | B12: ='CheckoutGuard — Assumptions (2)'!B9+'CheckoutGuard — Assumptions (2)'!B10+'CheckoutGuard — Assumptions · C'!B12+'CheckoutGuard — Assumptions · C'!B13+'CheckoutGuard — Assumptions · C'!B14+'CheckoutGuard — Assumptions (2)'!B11 -> 0.0190856
A13: Fixed monthly cost | B13: ='CheckoutGuard — Assumptions · C'!B20+'CheckoutGuard — Assumptions · C'!B21+'CheckoutGuard — Assumptions · C'!B22+'CheckoutGuard — Assumptions · C'!B23+'CheckoutGuard — Assumptions · C'!B24+'CheckoutGuard — Assumptions · C'!B25 -> 6800

Sheet CheckoutGuard — Assumptions · S
A1: CheckoutGuard — Assumptions · Sensitivity assumptions
A2: Financial model (3 pages) · Main Scenario
A4: Variable / dimension | B4: Value
A5: Payment processing rate | B5: =0.03 -> 0.03
A6: Payment transaction fee | B6: =0.3 -> 0.3
A7: Provider stress factor | B7: =10 -> 10
A8: Stress extra attempt ratio | B8: =1 -> 1
A9: Usage stress factor | B9: =2 -> 2
A10: Support stress factor | B10: =2 -> 2
A11: Browser stress factor | B11: =3 -> 3

Sheet CheckoutGuard — Forecast · Chec
A1: CheckoutGuard — Forecast · CheckoutGuard monthly forecast — assumptions
A2: Financial model (3 pages) · Main Scenario
A4: Variable / dimension | B4: 2026-10 | C4: 2026-11 | D4: 2026-12 | E4: 2027-01 | F4: 2027-02 | G4: 2027-03 | H4: 2027-04 | I4: 2027-05 | J4: 2027-06 | K4: 2027-07 | L4: 2027-08 | M4: 2027-09 | N4: 2027-10 | O4: 2027-11 | P4: 2027-12 | Q4: 2028-01 | R4: 2028-02 | S4: 2028-03 | T4: 2028-04 | U4: 2028-05 | V4: 2028-06 | W4: 2028-07 | X4: 2028-08 | Y4: 2028-09 | Z4: 2028-10
A5: Qualified prospects | B5: =SUM('CheckoutGuard — Forecast · Chec'!B6,'CheckoutGuard — Forecast · Chec'!B7,'CheckoutGuard — Forecast · Chec'!B8) -> 0 | C5: =SUM('CheckoutGuard — Forecast · Chec'!C6,'CheckoutGuard — Forecast · Chec'!C7,'CheckoutGuard — Forecast · Chec'!C8) -> 65 | D5: =SUM('CheckoutGuard — Forecast · Chec'!D6,'CheckoutGuard — Forecast · Chec'!D7,'CheckoutGuard — Forecast · Chec'!D8) -> 68.25 | E5: =SUM('CheckoutGuard — Forecast · Chec'!E6,'CheckoutGuard — Forecast · Chec'!E7,'CheckoutGuard — Forecast · Chec'!E8) -> 71.6625 | F5: =SUM('CheckoutGuard — Forecast · Chec'!F6,'CheckoutGuard — Forecast · Chec'!F7,'CheckoutGuard — Forecast · Chec'!F8) -> 75.245625 | G5: =SUM('CheckoutGuard — Forecast · Chec'!G6,'CheckoutGuard — Forecast · Chec'!G7,'CheckoutGuard — Forecast · Chec'!G8) -> 79.007906 | H5: =SUM('CheckoutGuard — Forecast · Chec'!H6,'CheckoutGuard — Forecast · Chec'!H7,'CheckoutGuard — Forecast · Chec'!H8) -> 82.958302 | I5: =SUM('CheckoutGuard — Forecast · Chec'!I6,'CheckoutGuard — Forecast · Chec'!I7,'CheckoutGuard — Forecast · Chec'!I8) -> 87.106217 | ... Z5: =SUM('CheckoutGuard — Forecast · Chec'!Z6,'CheckoutGuard — Forecast · Chec'!Z7,'CheckoutGuard — Forecast · Chec'!Z8) -> 199.64904
A6: Agency | B6: =0 -> 0 | C6: ='CheckoutGuard — Assumptions · W'!F5*IF(AND((1+'CheckoutGuard — Assumptions · C'!B18)=0,DATEDIF(DATE(2026,11,1),DATE(2026,11,1),"M")=0),SQRT(-1),(1+'CheckoutGuard — Assumptions · C'!B18)^DATEDIF(DATE(2026,11,1),DATE(2026,11,1),"M")) -> 5 | D6: ='CheckoutGuard — Assumptions · W'!F5*IF(AND((1+'CheckoutGuard — Assumptions · C'!B18)=0,DATEDIF(DATE(2026,11,1),DATE(2026,12,1),"M")=0),SQRT(-1),(1+'CheckoutGuard — Assumptions · C'!B18)^DATEDIF(DATE(2026,11,1),DATE(2026,12,1),"M")) -> 5.25 | E6: ='CheckoutGuard — Assumptions · W'!F5*IF(AND((1+'CheckoutGuard — Assumptions · C'!B18)=0,DATEDIF(DATE(2026,11,1),DATE(2027,1,1),"M")=0),SQRT(-1),(1+'CheckoutGuard — Assumptions · C'!B18)^DATEDIF(DATE(2026,11,1),DATE(2027,1,1),"M")) -> 5.5125 | F6: ='CheckoutGuard — Assumptions · W'!F5*IF(AND((1+'CheckoutGuard — Assumptions · C'!B18)=0,DATEDIF(DATE(2026,11,1),DATE(2027,2,1),"M")=0),SQRT(-1),(1+'CheckoutGuard — Assumptions · C'!B18)^DATEDIF(DATE(2026,11,1),DATE(2027,2,1),"M")) -> 5.788125 | G6: ='CheckoutGuard — Assumptions · W'!F5*IF(AND((1+'CheckoutGuard — Assumptions · C'!B18)=0,DATEDIF(DATE(2026,11,1),DATE(2027,3,1),"M")=0),SQRT(-1),(1+'CheckoutGuard — Assumptions · C'!B18)^DATEDIF(DATE(2026,11,1),DATE(2027,3,1),"M")) -> 6.0775313 | H6: ='CheckoutGuard — Assumptions · W'!F5*IF(AND((1+'CheckoutGuard — Assumptions · C'!B18)=0,DATEDIF(DATE(2026,11,1),DATE(2027,4,1),"M")=0),SQRT(-1),(1+'CheckoutGuard — Assumptions · C'!B18)^DATEDIF(DATE(2026,11,1),DATE(2027,4,1),"M")) -> 6.3814078 | I6: ='CheckoutGuard — Assumptions · W'!F5*IF(AND((1+'CheckoutGuard — Assumptions · C'!B18)=0,DATEDIF(DATE(2026,11,1),DATE(2027,5,1),"M")=0),SQRT(-1),(1+'CheckoutGuard — Assumptions · C'!B18)^DATEDIF(DATE(2026,11,1),DATE(2027,5,1),"M")) -> 6.7004782 | J6: ='CheckoutGuard — Assumptions · W'!F5*IF(AND((1+'CheckoutGuard — Assumptions · C'!B18)=0,DATEDIF(DATE(2026,11,1),DATE(2027,6,1),"M")=0),SQRT(-1),(1+'CheckoutGuard — Assumptions · C'!B18)^DATEDIF(DATE(2026,11,1),DATE(2027,6,1),"M")) -> 7.0355021 | K6: ='CheckoutGuard — Assumptions · W'!F5*IF(AND((1+'CheckoutGuard — Assumptions · C'!B18)=0,DATEDIF(DATE(2026,11,1),DATE(2027,7,1),"M")=0),SQRT(-1),(1+'CheckoutGuard — Assumptions · C'!B18)^DATEDIF(DATE(2026,11,1),DATE(2027,7,1),"M")) -> 7.3872772 | L6: ='CheckoutGuard — Assumptions · W'!F5*IF(AND((1+'CheckoutGuard — Assumptions · C'!B18)=0,DATEDIF(DATE(2026,11,1),DATE(2027,8,1),"M")=0),SQRT(-1),(1+'CheckoutGuard — Assumptions · C'!B18)^DATEDIF(DATE(2026,11,1),DATE(2027,8,1),"M")) -> 7.7566411 | M6: ='CheckoutGuard — Assumptions · W'!F5*IF(AND((1+'CheckoutGuard — Assumptions · C'!B18)=0,DATEDIF(DATE(2026,11,1),DATE(2027,9,1),"M")=0),SQRT(-1),(1+'CheckoutGuard — Assumptions · C'!B18)^DATEDIF(DATE(2026,11,1),DATE(2027,9,1),"M")) -> 8.1444731 | N6: ='CheckoutGuard — Assumptions · W'!F5*IF(AND((1+'CheckoutGuard — Assumptions · C'!B18)=0,DATEDIF(DATE(2026,11,1),DATE(2027,10,1),"M")=0),SQRT(-1),(1+'CheckoutGuard — Assumptions · C'!B18)^DATEDIF(DATE(2026,11,1),DATE(2027,10,1),"M")) -> 8.5516968 | O6: ='CheckoutGuard — Assumptions · W'!F5*IF(AND((1+'CheckoutGuard — Assumptions · C'!B18)=0,DATEDIF(DATE(2026,11,1),DATE(2027,11,1),"M")=0),SQRT(-1),(1+'CheckoutGuard — Assumptions · C'!B18)^DATEDIF(DATE(2026,11,1),DATE(2027,11,1),"M")) -> 8.9792816 | P6: ='CheckoutGuard — Assumptions · W'!F5*IF(AND((1+'CheckoutGuard — Assumptions · C'!B18)=0,DATEDIF(DATE(2026,11,1),DATE(2027,12,1),"M")=0),SQRT(-1),(1+'CheckoutGuard — Assumptions · C'!B18)^DATEDIF(DATE(2026,11,1),DATE(2027,12,1),"M")) -> 9.4282457 | Q6: ='CheckoutGuard — Assumptions · W'!F5*IF(AND((1+'CheckoutGuard — Assumptions · C'!B18)=0,DATEDIF(DATE(2026,11,1),DATE(2028,1,1),"M")=0),SQRT(-1),(1+'CheckoutGuard — Assumptions · C'!B18)^DATEDIF(DATE(2026,11,1),DATE(2028,1,1),"M")) -> 9.899658 | R6: ='CheckoutGuard — Assumptions · W'!F5*IF(AND((1+'CheckoutGuard — Assumptions · C'!B18)=0,DATEDIF(DATE(2026,11,1),DATE(2028,2,1),"M")=0),SQRT(-1),(1+'CheckoutGuard — Assumptions · C'!B18)^DATEDIF(DATE(2026,11,1),DATE(2028,2,1),"M")) -> 10.394641 | S6: ='CheckoutGuard — Assumptions · W'!F5*IF(AND((1+'CheckoutGuard — Assumptions · C'!B18)=0,DATEDIF(DATE(2026,11,1),DATE(2028,3,1),"M")=0),SQRT(-1),(1+'CheckoutGuard — Assumptions · C'!B18)^DATEDIF(DATE(2026,11,1),DATE(2028,3,1),"M")) -> 10.914373 | T6: ='CheckoutGuard — Assumptions · W'!F5*IF(AND((1+'CheckoutGuard — Assumptions · C'!B18)=0,DATEDIF(DATE(2026,11,1),DATE(2028,4,1),"M")=0),SQRT(-1),(1+'CheckoutGuard — Assumptions · C'!B18)^DATEDIF(DATE(2026,11,1),DATE(2028,4,1),"M")) -> 11.460092 | U6: ='CheckoutGuard — Assumptions · W'!F5*IF(AND((1+'CheckoutGuard — Assumptions · C'!B18)=0,DATEDIF(DATE(2026,11,1),DATE(2028,5,1),"M")=0),SQRT(-1),(1+'CheckoutGuard — Assumptions · C'!B18)^DATEDIF(DATE(2026,11,1),DATE(2028,5,1),"M")) -> 12.033096 | V6: ='CheckoutGuard — Assumptions · W'!F5*IF(AND((1+'CheckoutGuard — Assumptions · C'!B18)=0,DATEDIF(DATE(2026,11,1),DATE(2028,6,1),"M")=0),SQRT(-1),(1+'CheckoutGuard — Assumptions · C'!B18)^DATEDIF(DATE(2026,11,1),DATE(2028,6,1),"M")) -> 12.634751 | W6: ='CheckoutGuard — Assumptions · W'!F5*IF(AND((1+'CheckoutGuard — Assumptions · C'!B18)=0,DATEDIF(DATE(2026,11,1),DATE(2028,7,1),"M")=0),SQRT(-1),(1+'CheckoutGuard — Assumptions · C'!B18)^DATEDIF(DATE(2026,11,1),DATE(2028,7,1),"M")) -> 13.266489 | X6: ='CheckoutGuard — Assumptions · W'!F5*IF(AND((1+'CheckoutGuard — Assumptions · C'!B18)=0,DATEDIF(DATE(2026,11,1),DATE(2028,8,1),"M")=0),SQRT(-1),(1+'CheckoutGuard — Assumptions · C'!B18)^DATEDIF(DATE(2026,11,1),DATE(2028,8,1),"M")) -> 13.929813 | Y6: ='CheckoutGuard — Assumptions · W'!F5*IF(AND((1+'CheckoutGuard — Assumptions · C'!B18)=0,DATEDIF(DATE(2026,11,1),DATE(2028,9,1),"M")=0),SQRT(-1),(1+'CheckoutGuard — Assumptions · C'!B18)^DATEDIF(DATE(2026,11,1),DATE(2028,9,1),"M")) -> 14.626304 | Z6: ='CheckoutGuard — Assumptions · W'!F5*IF(AND((1+'CheckoutGuard — Assumptions · C'!B18)=0,DATEDIF(DATE(2026,11,1),DATE(2028,10,1),"M")=0),SQRT(-1),(1+'CheckoutGuard — Assumptions · C'!B18)^DATEDIF(DATE(2026,11,1),DATE(2028,10,1),"M")) -> 15.357619
A7: Developer | B7: =0 -> 0 | C7: ='CheckoutGuard — Assumptions · W'!F6*IF(AND((1+'CheckoutGuard — Assumptions · C'!B18)=0,DATEDIF(DATE(2026,11,1),DATE(2026,11,1),"M")=0),SQRT(-1),(1+'CheckoutGuard — Assumptions · C'!B18)^DATEDIF(DATE(2026,11,1),DATE(2026,11,1),"M")) -> 40 | D7: ='CheckoutGuard — Assumptions · W'!F6*IF(AND((1+'CheckoutGuard — Assumptions · C'!B18)=0,DATEDIF(DATE(2026,11,1),DATE(2026,12,1),"M")=0),SQRT(-1),(1+'CheckoutGuard — Assumptions · C'!B18)^DATEDIF(DATE(2026,11,1),DATE(2026,12,1),"M")) -> 42 | E7: ='CheckoutGuard — Assumptions · W'!F6*IF(AND((1+'CheckoutGuard — Assumptions · C'!B18)=0,DATEDIF(DATE(2026,11,1),DATE(2027,1,1),"M")=0),SQRT(-1),(1+'CheckoutGuard — Assumptions · C'!B18)^DATEDIF(DATE(2026,11,1),DATE(2027,1,1),"M")) -> 44.1 | F7: ='CheckoutGuard — Assumptions · W'!F6*IF(AND((1+'CheckoutGuard — Assumptions · C'!B18)=0,DATEDIF(DATE(2026,11,1),DATE(2027,2,1),"M")=0),SQRT(-1),(1+'CheckoutGuard — Assumptions · C'!B18)^DATEDIF(DATE(2026,11,1),DATE(2027,2,1),"M")) -> 46.305 | G7: ='CheckoutGuard — Assumptions · W'!F6*IF(AND((1+'CheckoutGuard — Assumptions · C'!B18)=0,DATEDIF(DATE(2026,11,1),DATE(2027,3,1),"M")=0),SQRT(-1),(1+'CheckoutGuard — Assumptions · C'!B18)^DATEDIF(DATE(2026,11,1),DATE(2027,3,1),"M")) -> 48.62025 | H7: ='CheckoutGuard — Assumptions · W'!F6*IF(AND((1+'CheckoutGuard — Assumptions · C'!B18)=0,DATEDIF(DATE(2026,11,1),DATE(2027,4,1),"M")=0),SQRT(-1),(1+'CheckoutGuard — Assumptions · C'!B18)^DATEDIF(DATE(2026,11,1),DATE(2027,4,1),"M")) -> 51.051263 | I7: ='CheckoutGuard — Assumptions · W'!F6*IF(AND((1+'CheckoutGuard — Assumptions · C'!B18)=0,DATEDIF(DATE(2026,11,1),DATE(2027,5,1),"M")=0),SQRT(-1),(1+'CheckoutGuard — Assumptions · C'!B18)^DATEDIF(DATE(2026,11,1),DATE(2027,5,1),"M")) -> 53.603826 | J7: ='CheckoutGuard — Assumptions · W'!F6*IF(AND((1+'CheckoutGuard — Assumptions · C'!B18)=0,DATEDIF(DATE(2026,11,1),DATE(2027,6,1),"M")=0),SQRT(-1),(1+'CheckoutGuard — Assumptions · C'!B18)^DATEDIF(DATE(2026,11,1),DATE(2027,6,1),"M")) -> 56.284017 | K7: ='CheckoutGuard — Assumptions · W'!F6*IF(AND((1+'CheckoutGuard — Assumptions · C'!B18)=0,DATEDIF(DATE(2026,11,1),DATE(2027,7,1),"M")=0),SQRT(-1),(1+'CheckoutGuard — Assumptions · C'!B18)^DATEDIF(DATE(2026,11,1),DATE(2027,7,1),"M")) -> 59.098218 | L7: ='CheckoutGuard — Assumptions · W'!F6*IF(AND((1+'CheckoutGuard — Assumptions · C'!B18)=0,DATEDIF(DATE(2026,11,1),DATE(2027,8,1),"M")=0),SQRT(-1),(1+'CheckoutGuard — Assumptions · C'!B18)^DATEDIF(DATE(2026,11,1),DATE(2027,8,1),"M")) -> 62.053129 | M7: ='CheckoutGuard — Assumptions · W'!F6*IF(AND((1+'CheckoutGuard — Assumptions · C'!B18)=0,DATEDIF(DATE(2026,11,1),DATE(2027,9,1),"M")=0),SQRT(-1),(1+'CheckoutGuard — Assumptions · C'!B18)^DATEDIF(DATE(2026,11,1),DATE(2027,9,1),"M")) -> 65.155785 | N7: ='CheckoutGuard — Assumptions · W'!F6*IF(AND((1+'CheckoutGuard — Assumptions · C'!B18)=0,DATEDIF(DATE(2026,11,1),DATE(2027,10,1),"M")=0),SQRT(-1),(1+'CheckoutGuard — Assumptions · C'!B18)^DATEDIF(DATE(2026,11,1),DATE(2027,10,1),"M")) -> 68.413574 | O7: ='CheckoutGuard — Assumptions · W'!F6*IF(AND((1+'CheckoutGuard — Assumptions · C'!B18)=0,DATEDIF(DATE(2026,11,1),DATE(2027,11,1),"M")=0),SQRT(-1),(1+'CheckoutGuard — Assumptions · C'!B18)^DATEDIF(DATE(2026,11,1),DATE(2027,11,1),"M")) -> 71.834253 | P7: ='CheckoutGuard — Assumptions · W'!F6*IF(AND((1+'CheckoutGuard — Assumptions · C'!B18)=0,DATEDIF(DATE(2026,11,1),DATE(2027,12,1),"M")=0),SQRT(-1),(1+'CheckoutGuard — Assumptions · C'!B18)^DATEDIF(DATE(2026,11,1),DATE(2027,12,1),"M")) -> 75.425966 | Q7: ='CheckoutGuard — Assumptions · W'!F6*IF(AND((1+'CheckoutGuard — Assumptions · C'!B18)=0,DATEDIF(DATE(2026,11,1),DATE(2028,1,1),"M")=0),SQRT(-1),(1+'CheckoutGuard — Assumptions · C'!B18)^DATEDIF(DATE(2026,11,1),DATE(2028,1,1),"M")) -> 79.197264 | R7: ='CheckoutGuard — Assumptions · W'!F6*IF(AND((1+'CheckoutGuard — Assumptions · C'!B18)=0,DATEDIF(DATE(2026,11,1),DATE(2028,2,1),"M")=0),SQRT(-1),(1+'CheckoutGuard — Assumptions · C'!B18)^DATEDIF(DATE(2026,11,1),DATE(2028,2,1),"M")) -> 83.157127 | S7: ='CheckoutGuard — Assumptions · W'!F6*IF(AND((1+'CheckoutGuard — Assumptions · C'!B18)=0,DATEDIF(DATE(2026,11,1),DATE(2028,3,1),"M")=0),SQRT(-1),(1+'CheckoutGuard — Assumptions · C'!B18)^DATEDIF(DATE(2026,11,1),DATE(2028,3,1),"M")) -> 87.314984 | T7: ='CheckoutGuard — Assumptions · W'!F6*IF(AND((1+'CheckoutGuard — Assumptions · C'!B18)=0,DATEDIF(DATE(2026,11,1),DATE(2028,4,1),"M")=0),SQRT(-1),(1+'CheckoutGuard — Assumptions · C'!B18)^DATEDIF(DATE(2026,11,1),DATE(2028,4,1),"M")) -> 91.680733 | U7: ='CheckoutGuard — Assumptions · W'!F6*IF(AND((1+'CheckoutGuard — Assumptions · C'!B18)=0,DATEDIF(DATE(2026,11,1),DATE(2028,5,1),"M")=0),SQRT(-1),(1+'CheckoutGuard — Assumptions · C'!B18)^DATEDIF(DATE(2026,11,1),DATE(2028,5,1),"M")) -> 96.264769 | V7: ='CheckoutGuard — Assumptions · W'!F6*IF(AND((1+'CheckoutGuard — Assumptions · C'!B18)=0,DATEDIF(DATE(2026,11,1),DATE(2028,6,1),"M")=0),SQRT(-1),(1+'CheckoutGuard — Assumptions · C'!B18)^DATEDIF(DATE(2026,11,1),DATE(2028,6,1),"M")) -> 101.07801 | W7: ='CheckoutGuard — Assumptions · W'!F6*IF(AND((1+'CheckoutGuard — Assumptions · C'!B18)=0,DATEDIF(DATE(2026,11,1),DATE(2028,7,1),"M")=0),SQRT(-1),(1+'CheckoutGuard — Assumptions · C'!B18)^DATEDIF(DATE(2026,11,1),DATE(2028,7,1),"M")) -> 106.13191 | X7: ='CheckoutGuard — Assumptions · W'!F6*IF(AND((1+'CheckoutGuard — Assumptions · C'!B18)=0,DATEDIF(DATE(2026,11,1),DATE(2028,8,1),"M")=0),SQRT(-1),(1+'CheckoutGuard — Assumptions · C'!B18)^DATEDIF(DATE(2026,11,1),DATE(2028,8,1),"M")) -> 111.4385 | Y7: ='CheckoutGuard — Assumptions · W'!F6*IF(AND((1+'CheckoutGuard — Assumptions · C'!B18)=0,DATEDIF(DATE(2026,11,1),DATE(2028,9,1),"M")=0),SQRT(-1),(1+'CheckoutGuard — Assumptions · C'!B18)^DATEDIF(DATE(2026,11,1),DATE(2028,9,1),"M")) -> 117.01043 | Z7: ='CheckoutGuard — Assumptions · W'!F6*IF(AND((1+'CheckoutGuard — Assumptions · C'!B18)=0,DATEDIF(DATE(2026,11,1),DATE(2028,10,1),"M")=0),SQRT(-1),(1+'CheckoutGuard — Assumptions · C'!B18)^DATEDIF(DATE(2026,11,1),DATE(2028,10,1),"M")) -> 122.86095
A8: Team | B8: =0 -> 0 | C8: ='CheckoutGuard — Assumptions · W'!F7*IF(AND((1+'CheckoutGuard — Assumptions · C'!B18)=0,DATEDIF(DATE(2026,11,1),DATE(2026,11,1),"M")=0),SQRT(-1),(1+'CheckoutGuard — Assumptions · C'!B18)^DATEDIF(DATE(2026,11,1),DATE(2026,11,1),"M")) -> 20 | D8: ='CheckoutGuard — Assumptions · W'!F7*IF(AND((1+'CheckoutGuard — Assumptions · C'!B18)=0,DATEDIF(DATE(2026,11,1),DATE(2026,12,1),"M")=0),SQRT(-1),(1+'CheckoutGuard — Assumptions · C'!B18)^DATEDIF(DATE(2026,11,1),DATE(2026,12,1),"M")) -> 21 | E8: ='CheckoutGuard — Assumptions · W'!F7*IF(AND((1+'CheckoutGuard — Assumptions · C'!B18)=0,DATEDIF(DATE(2026,11,1),DATE(2027,1,1),"M")=0),SQRT(-1),(1+'CheckoutGuard — Assumptions · C'!B18)^DATEDIF(DATE(2026,11,1),DATE(2027,1,1),"M")) -> 22.05 | F8: ='CheckoutGuard — Assumptions · W'!F7*IF(AND((1+'CheckoutGuard — Assumptions · C'!B18)=0,DATEDIF(DATE(2026,11,1),DATE(2027,2,1),"M")=0),SQRT(-1),(1+'CheckoutGuard — Assumptions · C'!B18)^DATEDIF(DATE(2026,11,1),DATE(2027,2,1),"M")) -> 23.1525 | G8: ='CheckoutGuard — Assumptions · W'!F7*IF(AND((1+'CheckoutGuard — Assumptions · C'!B18)=0,DATEDIF(DATE(2026,11,1),DATE(2027,3,1),"M")=0),SQRT(-1),(1+'CheckoutGuard — Assumptions · C'!B18)^DATEDIF(DATE(2026,11,1),DATE(2027,3,1),"M")) -> 24.310125 | H8: ='CheckoutGuard — Assumptions · W'!F7*IF(AND((1+'CheckoutGuard — Assumptions · C'!B18)=0,DATEDIF(DATE(2026,11,1),DATE(2027,4,1),"M")=0),SQRT(-1),(1+'CheckoutGuard — Assumptions · C'!B18)^DATEDIF(DATE(2026,11,1),DATE(2027,4,1),"M")) -> 25.525631 | I8: ='CheckoutGuard — Assumptions · W'!F7*IF(AND((1+'CheckoutGuard — Assumptions · C'!B18)=0,DATEDIF(DATE(2026,11,1),DATE(2027,5,1),"M")=0),SQRT(-1),(1+'CheckoutGuard — Assumptions · C'!B18)^DATEDIF(DATE(2026,11,1),DATE(2027,5,1),"M")) -> 26.801913 | J8: ='CheckoutGuard — Assumptions · W'!F7*IF(AND((1+'CheckoutGuard — Assumptions · C'!B18)=0,DATEDIF(DATE(2026,11,1),DATE(2027,6,1),"M")=0),SQRT(-1),(1+'CheckoutGuard — Assumptions · C'!B18)^DATEDIF(DATE(2026,11,1),DATE(2027,6,1),"M")) -> 28.142008 | K8: ='CheckoutGuard — Assumptions · W'!F7*IF(AND((1+'CheckoutGuard — Assumptions · C'!B18)=0,DATEDIF(DATE(2026,11,1),DATE(2027,7,1),"M")=0),SQRT(-1),(1+'CheckoutGuard — Assumptions · C'!B18)^DATEDIF(DATE(2026,11,1),DATE(2027,7,1),"M")) -> 29.549109 | L8: ='CheckoutGuard — Assumptions · W'!F7*IF(AND((1+'CheckoutGuard — Assumptions · C'!B18)=0,DATEDIF(DATE(2026,11,1),DATE(2027,8,1),"M")=0),SQRT(-1),(1+'CheckoutGuard — Assumptions · C'!B18)^DATEDIF(DATE(2026,11,1),DATE(2027,8,1),"M")) -> 31.026564 | M8: ='CheckoutGuard — Assumptions · W'!F7*IF(AND((1+'CheckoutGuard — Assumptions · C'!B18)=0,DATEDIF(DATE(2026,11,1),DATE(2027,9,1),"M")=0),SQRT(-1),(1+'CheckoutGuard — Assumptions · C'!B18)^DATEDIF(DATE(2026,11,1),DATE(2027,9,1),"M")) -> 32.577893 | N8: ='CheckoutGuard — Assumptions · W'!F7*IF(AND((1+'CheckoutGuard — Assumptions · C'!B18)=0,DATEDIF(DATE(2026,11,1),DATE(2027,10,1),"M")=0),SQRT(-1),(1+'CheckoutGuard — Assumptions · C'!B18)^DATEDIF(DATE(2026,11,1),DATE(2027,10,1),"M")) -> 34.206787 | O8: ='CheckoutGuard — Assumptions · W'!F7*IF(AND((1+'CheckoutGuard — Assumptions · C'!B18)=0,DATEDIF(DATE(2026,11,1),DATE(2027,11,1),"M")=0),SQRT(-1),(1+'CheckoutGuard — Assumptions · C'!B18)^DATEDIF(DATE(2026,11,1),DATE(2027,11,1),"M")) -> 35.917127 | P8: ='CheckoutGuard — Assumptions · W'!F7*IF(AND((1+'CheckoutGuard — Assumptions · C'!B18)=0,DATEDIF(DATE(2026,11,1),DATE(2027,12,1),"M")=0),SQRT(-1),(1+'CheckoutGuard — Assumptions · C'!B18)^DATEDIF(DATE(2026,11,1),DATE(2027,12,1),"M")) -> 37.712983 | Q8: ='CheckoutGuard — Assumptions · W'!F7*IF(AND((1+'CheckoutGuard — Assumptions · C'!B18)=0,DATEDIF(DATE(2026,11,1),DATE(2028,1,1),"M")=0),SQRT(-1),(1+'CheckoutGuard — Assumptions · C'!B18)^DATEDIF(DATE(2026,11,1),DATE(2028,1,1),"M")) -> 39.598632 | R8: ='CheckoutGuard — Assumptions · W'!F7*IF(AND((1+'CheckoutGuard — Assumptions · C'!B18)=0,DATEDIF(DATE(2026,11,1),DATE(2028,2,1),"M")=0),SQRT(-1),(1+'CheckoutGuard — Assumptions · C'!B18)^DATEDIF(DATE(2026,11,1),DATE(2028,2,1),"M")) -> 41.578564 | S8: ='CheckoutGuard — Assumptions · W'!F7*IF(AND((1+'CheckoutGuard — Assumptions · C'!B18)=0,DATEDIF(DATE(2026,11,1),DATE(2028,3,1),"M")=0),SQRT(-1),(1+'CheckoutGuard — Assumptions · C'!B18)^DATEDIF(DATE(2026,11,1),DATE(2028,3,1),"M")) -> 43.657492 | T8: ='CheckoutGuard — Assumptions · W'!F7*IF(AND((1+'CheckoutGuard — Assumptions · C'!B18)=0,DATEDIF(DATE(2026,11,1),DATE(2028,4,1),"M")=0),SQRT(-1),(1+'CheckoutGuard — Assumptions · C'!B18)^DATEDIF(DATE(2026,11,1),DATE(2028,4,1),"M")) -> 45.840366 | U8: ='CheckoutGuard — Assumptions · W'!F7*IF(AND((1+'CheckoutGuard — Assumptions · C'!B18)=0,DATEDIF(DATE(2026,11,1),DATE(2028,5,1),"M")=0),SQRT(-1),(1+'CheckoutGuard — Assumptions · C'!B18)^DATEDIF(DATE(2026,11,1),DATE(2028,5,1),"M")) -> 48.132385 | V8: ='CheckoutGuard — Assumptions · W'!F7*IF(AND((1+'CheckoutGuard — Assumptions · C'!B18)=0,DATEDIF(DATE(2026,11,1),DATE(2028,6,1),"M")=0),SQRT(-1),(1+'CheckoutGuard — Assumptions · C'!B18)^DATEDIF(DATE(2026,11,1),DATE(2028,6,1),"M")) -> 50.539004 | W8: ='CheckoutGuard — Assumptions · W'!F7*IF(AND((1+'CheckoutGuard — Assumptions · C'!B18)=0,DATEDIF(DATE(2026,11,1),DATE(2028,7,1),"M")=0),SQRT(-1),(1+'CheckoutGuard — Assumptions · C'!B18)^DATEDIF(DATE(2026,11,1),DATE(2028,7,1),"M")) -> 53.065954 | X8: ='CheckoutGuard — Assumptions · W'!F7*IF(AND((1+'CheckoutGuard — Assumptions · C'!B18)=0,DATEDIF(DATE(2026,11,1),DATE(2028,8,1),"M")=0),SQRT(-1),(1+'CheckoutGuard — Assumptions · C'!B18)^DATEDIF(DATE(2026,11,1),DATE(2028,8,1),"M")) -> 55.719252 | Y8: ='CheckoutGuard — Assumptions · W'!F7*IF(AND((1+'CheckoutGuard — Assumptions · C'!B18)=0,DATEDIF(DATE(2026,11,1),DATE(2028,9,1),"M")=0),SQRT(-1),(1+'CheckoutGuard — Assumptions · C'!B18)^DATEDIF(DATE(2026,11,1),DATE(2028,9,1),"M")) -> 58.505214 | Z8: ='CheckoutGuard — Assumptions · W'!F7*IF(AND((1+'CheckoutGuard — Assumptions · C'!B18)=0,DATEDIF(DATE(2026,11,1),DATE(2028,10,1),"M")=0),SQRT(-1),(1+'CheckoutGuard — Assumptions · C'!B18)^DATEDIF(DATE(2026,11,1),DATE(2028,10,1),"M")) -> 61.430475
A9: New paid subscriptions | B9: =SUM('CheckoutGuard — Forecast · Chec'!B10,'CheckoutGuard — Forecast · Chec'!B11,'CheckoutGuard — Forecast · Chec'!B12) -> 0 | C9: =SUM('CheckoutGuard — Forecast · Chec'!C10,'CheckoutGuard — Forecast · Chec'!C11,'CheckoutGuard — Forecast · Chec'!C12) -> 4.5 | D9: =SUM('CheckoutGuard — Forecast · Chec'!D10,'CheckoutGuard — Forecast · Chec'!D11,'CheckoutGuard — Forecast · Chec'!D12) -> 4.725 | E9: =SUM('CheckoutGuard — Forecast · Chec'!E10,'CheckoutGuard — Forecast · Chec'!E11,'CheckoutGuard — Forecast · Chec'!E12) -> 4.96125 | F9: =SUM('CheckoutGuard — Forecast · Chec'!F10,'CheckoutGuard — Forecast · Chec'!F11,'CheckoutGuard — Forecast · Chec'!F12) -> 5.2093125 | G9: =SUM('CheckoutGuard — Forecast · Chec'!G10,'CheckoutGuard — Forecast · Chec'!G11,'CheckoutGuard — Forecast · Chec'!G12) -> 5.4697781 | H9: =SUM('CheckoutGuard — Forecast · Chec'!H10,'CheckoutGuard — Forecast · Chec'!H11,'CheckoutGuard — Forecast · Chec'!H12) -> 5.743267 | I9: =SUM('CheckoutGuard — Forecast · Chec'!I10,'CheckoutGuard — Forecast · Chec'!I11,'CheckoutGuard — Forecast · Chec'!I12) -> 6.0304304 | ... Z9: =SUM('CheckoutGuard — Forecast · Chec'!Z10,'CheckoutGuard — Forecast · Chec'!Z11,'CheckoutGuard — Forecast · Chec'!Z12) -> 13.821857
A10: Agency | B10: ='CheckoutGuard — Forecast · Chec'!B6*'CheckoutGuard — Assumptions · W'!G5 -> 0 | C10: ='CheckoutGuard — Forecast · Chec'!C6*'CheckoutGuard — Assumptions · W'!G5 -> 0.5 | D10: ='CheckoutGuard — Forecast · Chec'!D6*'CheckoutGuard — Assumptions · W'!G5 -> 0.525 | E10: ='CheckoutGuard — Forecast · Chec'!E6*'CheckoutGuard — Assumptions · W'!G5 -> 0.55125 | F10: ='CheckoutGuard — Forecast · Chec'!F6*'CheckoutGuard — Assumptions · W'!G5 -> 0.5788125 | G10: ='CheckoutGuard — Forecast · Chec'!G6*'CheckoutGuard — Assumptions · W'!G5 -> 0.60775313 | H10: ='CheckoutGuard — Forecast · Chec'!H6*'CheckoutGuard — Assumptions · W'!G5 -> 0.63814078 | I10: ='CheckoutGuard — Forecast · Chec'!I6*'CheckoutGuard — Assumptions · W'!G5 -> 0.67004782 | J10: ='CheckoutGuard — Forecast · Chec'!J6*'CheckoutGuard — Assumptions · W'!G5 -> 0.70355021 | K10: ='CheckoutGuard — Forecast · Chec'!K6*'CheckoutGuard — Assumptions · W'!G5 -> 0.73872772 | L10: ='CheckoutGuard — Forecast · Chec'!L6*'CheckoutGuard — Assumptions · W'!G5 -> 0.77566411 | M10: ='CheckoutGuard — Forecast · Chec'!M6*'CheckoutGuard — Assumptions · W'!G5 -> 0.81444731 | N10: ='CheckoutGuard — Forecast · Chec'!N6*'CheckoutGuard — Assumptions · W'!G5 -> 0.85516968 | O10: ='CheckoutGuard — Forecast · Chec'!O6*'CheckoutGuard — Assumptions · W'!G5 -> 0.89792816 | P10: ='CheckoutGuard — Forecast · Chec'!P6*'CheckoutGuard — Assumptions · W'!G5 -> 0.94282457 | Q10: ='CheckoutGuard — Forecast · Chec'!Q6*'CheckoutGuard — Assumptions · W'!G5 -> 0.9899658 | R10: ='CheckoutGuard — Forecast · Chec'!R6*'CheckoutGuard — Assumptions · W'!G5 -> 1.0394641 | S10: ='CheckoutGuard — Forecast · Chec'!S6*'CheckoutGuard — Assumptions · W'!G5 -> 1.0914373 | T10: ='CheckoutGuard — Forecast · Chec'!T6*'CheckoutGuard — Assumptions · W'!G5 -> 1.1460092 | U10: ='CheckoutGuard — Forecast · Chec'!U6*'CheckoutGuard — Assumptions · W'!G5 -> 1.2033096 | V10: ='CheckoutGuard — Forecast · Chec'!V6*'CheckoutGuard — Assumptions · W'!G5 -> 1.2634751 | W10: ='CheckoutGuard — Forecast · Chec'!W6*'CheckoutGuard — Assumptions · W'!G5 -> 1.3266489 | X10: ='CheckoutGuard — Forecast · Chec'!X6*'CheckoutGuard — Assumptions · W'!G5 -> 1.3929813 | Y10: ='CheckoutGuard — Forecast · Chec'!Y6*'CheckoutGuard — Assumptions · W'!G5 -> 1.4626304 | Z10: ='CheckoutGuard — Forecast · Chec'!Z6*'CheckoutGuard — Assumptions · W'!G5 -> 1.5357619
A11: Developer | B11: ='CheckoutGuard — Forecast · Chec'!B7*'CheckoutGuard — Assumptions · W'!G6 -> 0 | C11: ='CheckoutGuard — Forecast · Chec'!C7*'CheckoutGuard — Assumptions · W'!G6 -> 2 | D11: ='CheckoutGuard — Forecast · Chec'!D7*'CheckoutGuard — Assumptions · W'!G6 -> 2.1 | E11: ='CheckoutGuard — Forecast · Chec'!E7*'CheckoutGuard — Assumptions · W'!G6 -> 2.205 | F11: ='CheckoutGuard — Forecast · Chec'!F7*'CheckoutGuard — Assumptions · W'!G6 -> 2.31525 | G11: ='CheckoutGuard — Forecast · Chec'!G7*'CheckoutGuard — Assumptions · W'!G6 -> 2.4310125 | H11: ='CheckoutGuard — Forecast · Chec'!H7*'CheckoutGuard — Assumptions · W'!G6 -> 2.5525631 | I11: ='CheckoutGuard — Forecast · Chec'!I7*'CheckoutGuard — Assumptions · W'!G6 -> 2.6801913 | J11: ='CheckoutGuard — Forecast · Chec'!J7*'CheckoutGuard — Assumptions · W'!G6 -> 2.8142008 | K11: ='CheckoutGuard — Forecast · Chec'!K7*'CheckoutGuard — Assumptions · W'!G6 -> 2.9549109 | L11: ='CheckoutGuard — Forecast · Chec'!L7*'CheckoutGuard — Assumptions · W'!G6 -> 3.1026564 | M11: ='CheckoutGuard — Forecast · Chec'!M7*'CheckoutGuard — Assumptions · W'!G6 -> 3.2577893 | N11: ='CheckoutGuard — Forecast · Chec'!N7*'CheckoutGuard — Assumptions · W'!G6 -> 3.4206787 | O11: ='CheckoutGuard — Forecast · Chec'!O7*'CheckoutGuard — Assumptions · W'!G6 -> 3.5917127 | P11: ='CheckoutGuard — Forecast · Chec'!P7*'CheckoutGuard — Assumptions · W'!G6 -> 3.7712983 | Q11: ='CheckoutGuard — Forecast · Chec'!Q7*'CheckoutGuard — Assumptions · W'!G6 -> 3.9598632 | R11: ='CheckoutGuard — Forecast · Chec'!R7*'CheckoutGuard — Assumptions · W'!G6 -> 4.1578564 | S11: ='CheckoutGuard — Forecast · Chec'!S7*'CheckoutGuard — Assumptions · W'!G6 -> 4.3657492 | T11: ='CheckoutGuard — Forecast · Chec'!T7*'CheckoutGuard — Assumptions · W'!G6 -> 4.5840366 | U11: ='CheckoutGuard — Forecast · Chec'!U7*'CheckoutGuard — Assumptions · W'!G6 -> 4.8132385 | V11: ='CheckoutGuard — Forecast · Chec'!V7*'CheckoutGuard — Assumptions · W'!G6 -> 5.0539004 | W11: ='CheckoutGuard — Forecast · Chec'!W7*'CheckoutGuard — Assumptions · W'!G6 -> 5.3065954 | X11: ='CheckoutGuard — Forecast · Chec'!X7*'CheckoutGuard — Assumptions · W'!G6 -> 5.5719252 | Y11: ='CheckoutGuard — Forecast · Chec'!Y7*'CheckoutGuard — Assumptions · W'!G6 -> 5.8505214 | Z11: ='CheckoutGuard — Forecast · Chec'!Z7*'CheckoutGuard — Assumptions · W'!G6 -> 6.1430475
